<?xml version="1.0" encoding="utf-8"?>
<!-- This URDF was automatically created by SolidWorks to URDF Exporter! Originally created by Stephen Brawner (brawner@gmail.com) 
     Commit Version: 1.5.1-0-g916b5db  Build Version: 1.5.7152.31018
     For more information, please see http://wiki.ros.org/sw_urdf_exporter -->
<robot
  name="trr_sw">

  <material name="black">
  <color rgba="0 0 0 0.7"/>
  </material>

  <link
    name="base_link">
    <inertial>
      <origin
        xyz="0 0 0.0242271293375395"
        rpy="0 0 0" />
      <mass
        value="5.97530922712779" />
      <inertia
        ixx="0.0168395692775663"
        ixy="1.49809859237117E-34"
        ixz="5.87747175411143E-36"
        iyy="0.0168395692775663"
        iyz="8.11874190175382E-19"
        izz="0.0312273524368662" />
    </inertial>
    <visual>
      <origin
        xyz="0 0 0"
        rpy="0 0 0" />
      <geometry>
        <mesh
          filename="file:///home/legacy/trr_robot_ws/src/robot/meshes/base_link.STL" />
      </geometry>
      <material
        name="">
        <color
          rgba="0.364705882352941 0.466666666666667 1 1" />
      </material>
    </visual>
    <collision>
      <origin
        xyz="0 0 0"
        rpy="0 0 0" />
      <geometry>
        <mesh
          filename="file:///home/legacy/trr_robot_ws/src/robot/meshes/base_link.STL" />
      </geometry>
      <contact_coefficients mu="0.1" kp="1000.0" kd="0.1"/>
    </collision>
  </link>
  <link
    name="Link_1">
    <inertial>
      <origin
        xyz="0.128214226709059 1.38777878078145E-17 0"
        rpy="0 0 0" />
      <mass
        value="0.407697682226567" />
      <inertia
        ixx="0.000163916122649683"
        ixy="-6.30057515429682E-19"
        ixz="9.52689050201753E-19"
        iyy="0.00657249406443876"
        iyz="-2.5410988417629E-20"
        izz="0.00654095603414877" />
    </inertial>
    <visual>
      <origin
        xyz="0 0 0"
        rpy="0 0 0" />
      <geometry>
        <mesh
          filename="file:///home/legacy/trr_robot_ws/src/robot/meshes/Link_1.STL" />
      </geometry>
      <material
        name="">
        <color
          rgba="1 0.913725490196078 0.0313725490196078 1" />
      </material>
    </visual>
    <collision>
      <origin
        xyz="0 0 0"
        rpy="0 0 0" />
      <geometry>
        <mesh
          filename="file:///home/legacy/trr_robot_ws/src/robot/meshes/Link_1.STL" />
      </geometry>
      <contact_coefficients mu="0.1" kp="1000.0" kd="0.1"/>
    </collision>
  </link>
  
  <link name="world" />
  <joint name="world_joint" type="fixed">
    <parent link="world" />
    <child link = "base_link" />
    <origin xyz="0.0 0.0 0.0" rpy="0.0 0.0 0.0" />
  </joint>
  <joint
    name="T_joint"
    type="continuous">
    <origin
      xyz="0 0 0.19042"
      rpy="1.574 -1.5708 0" />
    <parent
      link="base_link" />
    <child
      link="Link_1" />
    <axis
      xyz="1 0 0" />
  </joint>
  <link
    name="Link_1_pas">
    <inertial>
      <origin
        xyz="0 0.000899999999999845 0"
        rpy="0 0 0" />
      <mass
        value="0.0143848142541077" />
      <inertia
        ixx="1.9999690347498E-06"
        ixy="5.29395592033938E-23"
        ixz="-8.73157287821045E-23"
        iyy="7.17802950520689E-07"
        iyz="-8.29297031698427E-23"
        izz="1.9999690347498E-06" />
    </inertial>
    <visual>
      <origin
        xyz="0 0 0"
        rpy="0 0 0" />
      <geometry>
        <mesh
          filename="file:///home/legacy/trr_robot_ws/src/robot/meshes/Link_1_pas.STL" />
      </geometry>
      <material
        name="">
        <color
          rgba="0.792156862745098 0.819607843137255 0.933333333333333 1" />
      </material>
    </visual>
    <collision>
      <origin
        xyz="0 0 0"
        rpy="0 0 0" />
      <geometry>
        <mesh
          filename="file:///home/legacy/trr_robot_ws/src/robot/meshes/Link_1_pas.STL" />
      </geometry>
      <contact_coefficients mu="0.1" kp="1000.0" kd="0.1"/>
    </collision>
  </link>
  <joint
    name="T_joint_pas"
    type="fixed">
    <origin
      xyz="0.242 0 0"
      rpy="-1.5708 0 -1.5686" />
    <parent
      link="Link_1" />
    <child
      link="Link_1_pas" />
    <axis
      xyz="0 0 0" />
  </joint>
  <link
    name="Link_2">
    <inertial>
      <origin
        xyz="1.50920942409982E-15 -1.38777878078145E-16 0.125"
        rpy="0 0 0" />
      <mass
        value="0.283850401769183" />
      <inertia
        ixx="0.00165969308106523"
        ixy="-8.470329472543E-22"
        ixz="-1.61631763476206E-17"
        iyy="0.00167439428296371"
        iyz="-1.62793823290776E-19"
        izz="4.47439284217344E-05" />
    </inertial>
    <visual>
      <origin
        xyz="0 0 0"
        rpy="0 0 0" />
      <geometry>
        <mesh
          filename="file:///home/legacy/trr_robot_ws/src/robot/meshes/Link_2.STL" />
      </geometry>
      <material
        name="">
        <color
          rgba="1 0.913725490196078 0.0313725490196078 1" />
      </material>
    </visual>
    <collision>
      <origin
        xyz="0 0 0"
        rpy="0 0 0" />
      <geometry>
        <mesh
          filename="file:///home/legacy/trr_robot_ws/src/robot/meshes/Link_2.STL" />
      </geometry>
      <contact_coefficients mu="0.1" kp="1000.0" kd="0.1"/>
    </collision>
  </link>
  <joint
    name="R1_joint"
    type="continuous">
    <origin
      xyz="0 0 0"
      rpy="0 0 0" />
    <parent
      link="Link_1_pas" />
    <child
      link="Link_2" />
    <axis
      xyz="0 1 0" />
  </joint>
  <link
    name="Link_2_pas">
    <inertial>
      <origin
        xyz="-3.46944695195361E-18 -0.000899999999999845 0"
        rpy="0 0 0" />
      <mass
        value="0.0143848142541077" />
      <inertia
        ixx="1.9999690347498E-06"
        ixy="6.61744490042422E-23"
        ixz="-4.0005471532037E-24"
        iyy="7.17802950520688E-07"
        iyz="4.8496694585189E-23"
        izz="1.9999690347498E-06" />
    </inertial>
    <visual>
      <origin
        xyz="0 0 0"
        rpy="0 0 0" />
      <geometry>
        <mesh
          filename="file:///home/legacy/trr_robot_ws/src/robot/meshes/Link_2_pas.STL" />
      </geometry>
      <material
        name="">
        <color
          rgba="0.792156862745098 0.819607843137255 0.933333333333333 1" />
      </material>
    </visual>
    <collision>
      <origin
        xyz="0 0 0"
        rpy="0 0 0" />
      <geometry>
        <mesh
          filename="file:///home/legacy/trr_robot_ws/src/robot/meshes/Link_2_pas.STL" />
      </geometry>
      <contact_coefficients mu="0.1" kp="1000.0" kd="0.1"/>
    </collision>
  </link>
  <joint
    name="R1_joint_pas"
    type="fixed">
    <origin
      xyz="0 0 0.25"
      rpy="0 -0.015943 0" />
    <parent
      link="Link_2" />
    <child
      link="Link_2_pas" />
    <axis
      xyz="0 0 0" />
  </joint>
  <link
    name="Link_3">
    <inertial>
      <origin
        xyz="5.74540415243519E-15 -0.210765320384387 4.9960036108132E-16"
        rpy="0 0 0" />
      <mass
        value="0.263589855358481" />
      <inertia
        ixx="0.00372379351618934"
        ixy="1.00918893467666E-16"
        ixz="-5.63678351015139E-22"
        iyy="9.02562980095516E-05"
        iyz="6.76504436831097E-18"
        izz="0.00375533109358108" />
    </inertial>
    <visual>
      <origin
        xyz="0 0 0"
        rpy="0 0 0" />
      <geometry>
        <mesh
          filename="file:///home/legacy/trr_robot_ws/src/robot/meshes/Link_3.STL" />
      </geometry>
      <material
        name="">
        <color
          rgba="1 0.913725490196078 0.0313725490196078 1" />
      </material>
    </visual>
    <collision>
      <origin
        xyz="0 0 0"
        rpy="0 0 0" />
      <geometry>
        <mesh
          filename="file:///home/legacy/trr_robot_ws/src/robot/meshes/Link_3.STL" />
      </geometry>
      <contact_coefficients mu="0.1" kp="1000.0" kd="0.1"/>
    </collision>
  </link>
  <joint
    name="R2_joint"
    type="continuous">
    <origin
      xyz="0 0 0"
      rpy="3.1234 0 -1.5708" />
    <parent
      link="Link_2_pas" />
    <child
      link="Link_3" />
    <axis
      xyz="1 0 0" />
  </joint>

<!--LIDAR SETUP-->

  <link name="Lidar_link">
  <inertial>
    <origin xyz="0 0 0" rpy="0 0 0"/>
    <mass value="0.125"/>
    <inertia ixx="0.001"  ixy="0"  ixz="0" iyy="0.001" iyz="0" izz="0.001" />
  </inertial>

  <collision>
    <origin xyz="0 0 0" rpy="0 0 0"/>
    <geometry>
       <cylinder radius="0.03" length="0.07"/>
    </geometry>
  </collision>

  <visual>
    <origin xyz="0 0 0" rpy="0 0 0"/>
    <geometry>
       <cylinder radius="0.016" length="0.12"/>
    </geometry>
    <material name="black"/>
  </visual>
  </link>

  <joint
    name="Lidar_joint"
    type="fixed">
    <origin
      xyz="0 -0.4 0"
      rpy="0 0 0" />
    <parent
      link="Link_1" />
    <child
      link="Lidar_link" />
    <axis
      xyz="1 0 0" />
  </joint>

  <gazebo reference="Lidar_link">
  <sensor name="lidar" type="ray">
    <always_on>true</always_on>
    <visualize>true</visualize>
    <update_rate>5</update_rate>
    <ray>
      <scan>
        <horizontal>
          <samples>120</samples>
          <resolution>1.000000</resolution>
          <min_angle>-3.14159</min_angle>
          <max_angle>3.14159</max_angle>
        </horizontal>
      </scan>
      <range>
        <min>0.15</min>
        <max>15.0</max>
        <resolution>0.015</resolution>
      </range>
      <noise>
        <type>gaussian</type>
        <mean>0.0</mean>
        <stddev>0.01</stddev>
      </noise>
    </ray>
    <plugin name="scan" filename="libgazebo_ros_ray_sensor.so">
      <ros>
        <remapping>~/out:=scan</remapping>
      </ros>
      <output_type>sensor_msgs/LaserScan</output_type>
      <frame_name>Lidar_link</frame_name>
    </plugin>
  </sensor>
  </gazebo>
  <gazebo reference="Lidar_link">
    <mu1>0.01</mu1>
    <mu2>0.01</mu2>
    <material>Gazebo/Black</material>
  </gazebo>


    <!-- Torsional Gazebo Joint config -->
  <ros2_control name="GazeboSystem" type="system">
    <hardware>
      <plugin>gazebo_ros2_control/GazeboSystem</plugin>
    </hardware>    
    <joint name="T_joint">
      <command_interface name="position">
        <param name="min">-3.14159</param>
        <param name="max">3.14159</param>
      </command_interface>
      <state_interface name="position"/>
      <state_interface name="velocity"/>
      <state_interface name="effort"/>
    </joint>
  </ros2_control>

    <!-- R1 Gazebo Joint config -->
  <ros2_control name="GazeboSystem" type="system">
    <hardware>
      <plugin>gazebo_ros2_control/GazeboSystem</plugin>
    </hardware>    
    <joint name="R1_joint">
      <command_interface name="position">
        <param name="min">-3.14159</param>
        <param name="max">3.14159</param>
      </command_interface>
      <state_interface name="position"/>
      <state_interface name="velocity"/>
      <state_interface name="effort"/>
    </joint>
  </ros2_control>

    <!-- R2 Gazebo Joint config -->
  <ros2_control name="GazeboSystem" type="system">
    <hardware>
      <plugin>gazebo_ros2_control/GazeboSystem</plugin>
    </hardware>    
    <joint name="R2_joint">
      <command_interface name="position">
        <param name="min">-3.14159</param>
        <param name="max">3.14159</param>
      </command_interface>
      <state_interface name="position"/>
      <state_interface name="velocity"/>
      <state_interface name="effort"/>
    </joint>
  </ros2_control>


  <gazebo>
    <plugin filename="libgazebo_ros2_control.so" name="gazebo_ros2_control">
      <!-- <parameters>$(find box_car_description)/config/steering_controller_velocity.yaml</parameters> -->
      <parameters>/home/legacy/trr_robot_ws/src/robot/config/joint_controller.yaml</parameters>
    </plugin>
  </gazebo>

</robot>
