<sdf version='1.7'>
  <world name='default'>
    <light name='sun' type='directional'>
      <cast_shadows>1</cast_shadows>
      <pose>0 0 10 0 -0 0</pose>
      <diffuse>0.8 0.8 0.8 1</diffuse>
      <specular>0.2 0.2 0.2 1</specular>
      <attenuation>
        <range>1000</range>
        <constant>0.9</constant>
        <linear>0.01</linear>
        <quadratic>0.001</quadratic>
      </attenuation>
      <direction>-0.5 0.1 -0.9</direction>
      <spot>
        <inner_angle>0</inner_angle>
        <outer_angle>0</outer_angle>
        <falloff>0</falloff>
      </spot>
    </light>
    <model name='ground_plane'>
      <static>1</static>
      <link name='link'>
        <collision name='collision'>
          <geometry>
            <plane>
              <normal>0 0 1</normal>
              <size>100 100</size>
            </plane>
          </geometry>
          <surface>
            <friction>
              <ode>
                <mu>100</mu>
                <mu2>50</mu2>
              </ode>
              <torsional>
                <ode/>
              </torsional>
            </friction>
            <contact>
              <ode/>
            </contact>
            <bounce/>
          </surface>
          <max_contacts>10</max_contacts>
        </collision>
        <visual name='visual'>
          <cast_shadows>0</cast_shadows>
          <geometry>
            <plane>
              <normal>0 0 1</normal>
              <size>100 100</size>
            </plane>
          </geometry>
          <material>
            <script>
              <uri>file://media/materials/scripts/gazebo.material</uri>
              <name>Gazebo/Grey</name>
            </script>
          </material>
        </visual>
        <self_collide>0</self_collide>
        <enable_wind>0</enable_wind>
        <kinematic>0</kinematic>
      </link>
    </model>
    <gravity>0 0 -9.8</gravity>
    <magnetic_field>6e-06 2.3e-05 -4.2e-05</magnetic_field>
    <atmosphere type='adiabatic'/>
    <physics type='ode'>
      <max_step_size>0.001</max_step_size>
      <real_time_factor>1</real_time_factor>
      <real_time_update_rate>1000</real_time_update_rate>
    </physics>
    <scene>
      <ambient>0.4 0.4 0.4 1</ambient>
      <background>0.7 0.7 0.7 1</background>
      <shadows>1</shadows>
    </scene>
    <wind/>
    <spherical_coordinates>
      <surface_model>EARTH_WGS84</surface_model>
      <latitude_deg>0</latitude_deg>
      <longitude_deg>0</longitude_deg>
      <elevation>0</elevation>
      <heading_deg>0</heading_deg>
    </spherical_coordinates>
    <model name='robot'>
      <joint name='world_joint' type='fixed'>
        <pose relative_to='__model__'>0 0 0 0 -0 0</pose>
        <parent>world</parent>
        <child>base_link</child>
      </joint>
      <link name='base_link'>
        <pose relative_to='world_joint'>0 0 0 0 -0 0</pose>
        <inertial>
          <pose>0 0 0.024227 0 -0 0</pose>
          <mass>5.97531</mass>
          <inertia>
            <ixx>0.0168396</ixx>
            <ixy>1.4981e-34</ixy>
            <ixz>5.87747e-36</ixz>
            <iyy>0.0168396</iyy>
            <iyz>8.11874e-19</iyz>
            <izz>0.0312274</izz>
          </inertia>
        </inertial>
        <collision name='base_link_collision'>
          <pose>0 0 0 0 -0 0</pose>
          <geometry>
            <mesh>
              <scale>1 1 1</scale>
              <uri>file:///home/legacy/trr_robot_ws/src/robot/meshes/base_link.STL</uri>
            </mesh>
          </geometry>
          <max_contacts>10</max_contacts>
          <surface>
            <contact>
              <ode/>
            </contact>
            <bounce/>
            <friction>
              <torsional>
                <ode/>
              </torsional>
              <ode/>
            </friction>
          </surface>
        </collision>
        <visual name='base_link_visual'>
          <pose>0 0 0 0 -0 0</pose>
          <geometry>
            <mesh>
              <scale>1 1 1</scale>
              <uri>file:///home/legacy/trr_robot_ws/src/robot/meshes/base_link.STL</uri>
            </mesh>
          </geometry>
        </visual>
        <self_collide>0</self_collide>
        <enable_wind>0</enable_wind>
        <kinematic>0</kinematic>
      </link>
      <joint name='T_joint' type='revolute'>
        <pose relative_to='base_link'>0 0 0.19042 -1.56759 -1.57079 3.14159</pose>
        <parent>base_link</parent>
        <child>Link_1</child>
        <axis>
          <xyz>1 0 0</xyz>
          <limit>
            <lower>-1e+16</lower>
            <upper>1e+16</upper>
          </limit>
          <dynamics>
            <spring_reference>0</spring_reference>
            <spring_stiffness>0</spring_stiffness>
          </dynamics>
        </axis>
      </joint>
      <link name='Link_1'>
        <pose relative_to='T_joint'>0 0 0 0 -0 0</pose>
        <inertial>
          <pose>0.132092 -0 -3.1e-05 0 -0 0</pose>
          <mass>0.422082</mass>
          <inertia>
            <ixx>0.000165927</ixx>
            <ixy>1.14787e-14</ixy>
            <ixz>1.4229e-06</ixz>
            <iyy>0.0067544</iyy>
            <iyz>-1.04348e-14</iyz>
            <izz>0.00672157</izz>
          </inertia>
        </inertial>
        <collision name='Link_1_collision'>
          <pose>0 0 0 0 -0 0</pose>
          <geometry>
            <mesh>
              <scale>1 1 1</scale>
              <uri>file:///home/legacy/trr_robot_ws/src/robot/meshes/Link_1.STL</uri>
            </mesh>
          </geometry>
          <max_contacts>10</max_contacts>
          <surface>
            <contact>
              <ode/>
            </contact>
            <bounce/>
            <friction>
              <torsional>
                <ode/>
              </torsional>
              <ode/>
            </friction>
          </surface>
        </collision>
        <collision name='Link_1_pas_collision_1'>
          <pose>0.242 0 0 -1.5708 -0 -1.5686</pose>
          <geometry>
            <mesh>
              <scale>1 1 1</scale>
              <uri>file:///home/legacy/trr_robot_ws/src/robot/meshes/Link_1_pas.STL</uri>
            </mesh>
          </geometry>
          <max_contacts>10</max_contacts>
          <surface>
            <contact>
              <ode/>
            </contact>
            <bounce/>
            <friction>
              <torsional>
                <ode/>
              </torsional>
              <ode/>
            </friction>
          </surface>
        </collision>
        <visual name='Link_1_visual'>
          <pose>0 0 0 0 -0 0</pose>
          <geometry>
            <mesh>
              <scale>1 1 1</scale>
              <uri>file:///home/legacy/trr_robot_ws/src/robot/meshes/Link_1.STL</uri>
            </mesh>
          </geometry>
        </visual>
        <visual name='Link_1_pas_visual_1'>
          <pose>0.242 0 0 -1.5708 -0 -1.5686</pose>
          <geometry>
            <mesh>
              <scale>1 1 1</scale>
              <uri>file:///home/legacy/trr_robot_ws/src/robot/meshes/Link_1_pas.STL</uri>
            </mesh>
          </geometry>
        </visual>
        <self_collide>0</self_collide>
        <enable_wind>0</enable_wind>
        <kinematic>0</kinematic>
      </link>
      <joint name='R1_joint' type='revolute'>
        <pose relative_to='Link_1'>0.242 0 0 -1.5708 -0 -1.5686</pose>
        <parent>Link_1</parent>
        <child>Link_2</child>
        <axis>
          <xyz>0 1 0</xyz>
          <limit>
            <lower>-1e+16</lower>
            <upper>1e+16</upper>
          </limit>
          <dynamics>
            <spring_reference>0</spring_reference>
            <spring_stiffness>0</spring_stiffness>
          </dynamics>
        </axis>
      </joint>
      <link name='Link_2'>
        <pose relative_to='R1_joint'>0 0 0 0 -0 0</pose>
        <inertial>
          <pose>0 -4.3e-05 0.131029 0 -0 0</pose>
          <mass>0.298235</mass>
          <inertia>
            <ixx>0.00187563</ixx>
            <ixy>-1.94207e-20</ixy>
            <ixz>-1.35744e-17</ixz>
            <iyy>0.00188903</iyy>
            <iyz>1.54024e-06</iyz>
            <izz>4.6755e-05</izz>
          </inertia>
        </inertial>
        <collision name='Link_2_collision'>
          <pose>0 0 0 0 -0 0</pose>
          <geometry>
            <mesh>
              <scale>1 1 1</scale>
              <uri>file:///home/legacy/trr_robot_ws/src/robot/meshes/Link_2.STL</uri>
            </mesh>
          </geometry>
          <max_contacts>10</max_contacts>
          <surface>
            <contact>
              <ode/>
            </contact>
            <bounce/>
            <friction>
              <torsional>
                <ode/>
              </torsional>
              <ode/>
            </friction>
          </surface>
        </collision>
        <collision name='Link_2_pas_collision_1'>
          <pose>0 0 0.25 0 -0.015943 0</pose>
          <geometry>
            <mesh>
              <scale>1 1 1</scale>
              <uri>file:///home/legacy/trr_robot_ws/src/robot/meshes/Link_2_pas.STL</uri>
            </mesh>
          </geometry>
          <max_contacts>10</max_contacts>
          <surface>
            <contact>
              <ode/>
            </contact>
            <bounce/>
            <friction>
              <torsional>
                <ode/>
              </torsional>
              <ode/>
            </friction>
          </surface>
        </collision>
        <visual name='Link_2_visual'>
          <pose>0 0 0 0 -0 0</pose>
          <geometry>
            <mesh>
              <scale>1 1 1</scale>
              <uri>file:///home/legacy/trr_robot_ws/src/robot/meshes/Link_2.STL</uri>
            </mesh>
          </geometry>
        </visual>
        <visual name='Link_2_pas_visual_1'>
          <pose>0 0 0.25 0 -0.015943 0</pose>
          <geometry>
            <mesh>
              <scale>1 1 1</scale>
              <uri>file:///home/legacy/trr_robot_ws/src/robot/meshes/Link_2_pas.STL</uri>
            </mesh>
          </geometry>
        </visual>
        <self_collide>0</self_collide>
        <enable_wind>0</enable_wind>
        <kinematic>0</kinematic>
      </link>
      <joint name='R2_joint' type='revolute'>
        <pose relative_to='Link_2'>0 0 0.25 3.13934 0 -1.5708</pose>
        <parent>Link_2</parent>
        <child>Link_3</child>
        <axis>
          <xyz>1 0 0</xyz>
          <limit>
            <lower>-1e+16</lower>
            <upper>1e+16</upper>
          </limit>
          <dynamics>
            <spring_reference>0</spring_reference>
            <spring_stiffness>0</spring_stiffness>
          </dynamics>
        </axis>
      </joint>
      <link name='Link_3'>
        <pose relative_to='R2_joint'>0 0 0 0 -0 0</pose>
        <inertial>
          <pose>0 -0.210765 0 0 -0 0</pose>
          <mass>0.26359</mass>
          <inertia>
            <ixx>0.00372379</ixx>
            <ixy>1.00919e-16</ixy>
            <ixz>-5.63678e-22</ixz>
            <iyy>9.02563e-05</iyy>
            <iyz>6.76504e-18</iyz>
            <izz>0.00375533</izz>
          </inertia>
        </inertial>
        <collision name='Link_3_collision'>
          <pose>0 0 0 0 -0 0</pose>
          <geometry>
            <mesh>
              <scale>1 1 1</scale>
              <uri>file:///home/legacy/trr_robot_ws/src/robot/meshes/Link_3.STL</uri>
            </mesh>
          </geometry>
          <max_contacts>10</max_contacts>
          <surface>
            <contact>
              <ode/>
            </contact>
            <bounce/>
            <friction>
              <torsional>
                <ode/>
              </torsional>
              <ode/>
            </friction>
          </surface>
        </collision>
        <visual name='Link_3_visual'>
          <pose>0 0 0 0 -0 0</pose>
          <geometry>
            <mesh>
              <scale>1 1 1</scale>
              <uri>file:///home/legacy/trr_robot_ws/src/robot/meshes/Link_3.STL</uri>
            </mesh>
          </geometry>
        </visual>
        <self_collide>0</self_collide>
        <enable_wind>0</enable_wind>
        <kinematic>0</kinematic>
      </link>
      <static>0</static>
      <plugin name='gazebo_ros2_control' filename='libgazebo_ros2_control.so'>
        <parameters>/home/legacy/trr_robot_ws/src/robot/config/joint_controller.yaml</parameters>
      </plugin>
      <pose>0 0 0 0 -0 0</pose>
    </model>
    <state world_name='default'>
      <sim_time>292 608000000</sim_time>
      <real_time>293 211868121</real_time>
      <wall_time>1639589135 409325950</wall_time>
      <iterations>292608</iterations>
      <model name='ground_plane'>
        <pose>0 0 0 0 -0 0</pose>
        <scale>1 1 1</scale>
        <link name='link'>
          <pose>0 0 0 0 -0 0</pose>
          <velocity>0 0 0 0 -0 0</velocity>
          <acceleration>0 0 0 0 -0 0</acceleration>
          <wrench>0 0 0 0 -0 0</wrench>
        </link>
      </model>
      <model name='robot'>
        <pose>0 0 0 0 -0 0</pose>
        <scale>1 1 1</scale>
        <link name='Link_1'>
          <pose>-0 -0 0.19042 0.438464 -1.57079 3.13554</pose>
          <velocity>2.1e-05 1e-05 0 -0.000246 1e-06 1.15222</velocity>
          <acceleration>6.2e-05 -0.000109 -0 0.232201 -0.302928 -0.185992</acceleration>
          <wrench>2.6e-05 -4.6e-05 -0 0 -0 0</wrench>
        </link>
        <link name='Link_2'>
          <pose>-0.000331 0.002926 0.431421 -3.12039 1.14371 -1.11909</pose>
          <velocity>0.065963 -0.585086 0.199883 2.76873 1.38195 -1.19568</velocity>
          <acceleration>-0.562396 -0.080687 0.481026 -1.02012 0.205738 0.296644</acceleration>
          <wrench>-0.167726 -0.024064 0.143459 0 -0 0</wrench>
        </link>
        <link name='Link_3'>
          <pose>-0.098832 0.225385 0.318229 3.14142 0.018925 0.432474</pose>
          <velocity>-11.4311 0.990135 22.6921 0.39978 -0.586348 -2.41773</velocity>
          <acceleration>-2.0443 -0.608258 0.707791 -0.603966 0.706776 1.56191</acceleration>
          <wrench>-0.538858 -0.160331 0.186567 0 -0 0</wrench>
        </link>
        <link name='base_link'>
          <pose>0 0 0 0 -0 0</pose>
          <velocity>0 0 0 -0 -0 -0</velocity>
          <acceleration>0 -0 -0 1e-06 7e-06 1e-06</acceleration>
          <wrench>1e-06 -0 -1e-06 0 -0 0</wrench>
        </link>
      </model>
      <light name='sun'>
        <pose>0 0 10 0 -0 0</pose>
      </light>
    </state>
    <gui fullscreen='0'>
      <camera name='user_camera'>
        <pose>-0.135556 0.248511 0.588988 0 1.3818 -0.019804</pose>
        <view_controller>orbit</view_controller>
        <projection_type>perspective</projection_type>
      </camera>
    </gui>
  </world>
</sdf>
