<sdf version='1.7'>
  <world name='default'>
    <light name='sun' type='directional'>
      <cast_shadows>1</cast_shadows>
      <pose>0 0 10 0 -0 0</pose>
      <diffuse>0.8 0.8 0.8 1</diffuse>
      <specular>0.2 0.2 0.2 1</specular>
      <attenuation>
        <range>1000</range>
        <constant>0.9</constant>
        <linear>0.01</linear>
        <quadratic>0.001</quadratic>
      </attenuation>
      <direction>-0.5 0.1 -0.9</direction>
      <spot>
        <inner_angle>0</inner_angle>
        <outer_angle>0</outer_angle>
        <falloff>0</falloff>
      </spot>
    </light>
    <model name='ground_plane'>
      <static>1</static>
      <link name='link'>
        <collision name='collision'>
          <geometry>
            <plane>
              <normal>0 0 1</normal>
              <size>100 100</size>
            </plane>
          </geometry>
          <surface>
            <friction>
              <ode>
                <mu>100</mu>
                <mu2>50</mu2>
              </ode>
              <torsional>
                <ode/>
              </torsional>
            </friction>
            <contact>
              <ode/>
            </contact>
            <bounce/>
          </surface>
          <max_contacts>10</max_contacts>
        </collision>
        <visual name='visual'>
          <cast_shadows>0</cast_shadows>
          <geometry>
            <plane>
              <normal>0 0 1</normal>
              <size>100 100</size>
            </plane>
          </geometry>
          <material>
            <script>
              <uri>file://media/materials/scripts/gazebo.material</uri>
              <name>Gazebo/Grey</name>
            </script>
          </material>
        </visual>
        <self_collide>0</self_collide>
        <enable_wind>0</enable_wind>
        <kinematic>0</kinematic>
      </link>
    </model>
    <gravity>0 0 -9.8</gravity>
    <magnetic_field>6e-06 2.3e-05 -4.2e-05</magnetic_field>
    <atmosphere type='adiabatic'/>
    <physics type='ode'>
      <max_step_size>0.001</max_step_size>
      <real_time_factor>1</real_time_factor>
      <real_time_update_rate>1000</real_time_update_rate>
    </physics>
    <scene>
      <ambient>0.4 0.4 0.4 1</ambient>
      <background>0.7 0.7 0.7 1</background>
      <shadows>1</shadows>
    </scene>
    <wind/>
    <spherical_coordinates>
      <surface_model>EARTH_WGS84</surface_model>
      <latitude_deg>0</latitude_deg>
      <longitude_deg>0</longitude_deg>
      <elevation>0</elevation>
      <heading_deg>0</heading_deg>
    </spherical_coordinates>
    <model name='robot'>
      <joint name='world_joint' type='fixed'>
        <pose relative_to='__model__'>0 0 0 0 -0 0</pose>
        <parent>world</parent>
        <child>base_link</child>
      </joint>
      <link name='base_link'>
        <pose relative_to='world_joint'>0 0 0 0 -0 0</pose>
        <inertial>
          <pose>0 0 0.024227 0 -0 0</pose>
          <mass>5.97531</mass>
          <inertia>
            <ixx>0.0168396</ixx>
            <ixy>1.4981e-34</ixy>
            <ixz>5.87747e-36</ixz>
            <iyy>0.0168396</iyy>
            <iyz>8.11874e-19</iyz>
            <izz>0.0312274</izz>
          </inertia>
        </inertial>
        <collision name='base_link_collision'>
          <pose>0 0 0 0 -0 0</pose>
          <geometry>
            <mesh>
              <scale>1 1 1</scale>
              <uri>file:///home/legacy/trr_robot_ws/src/robot/meshes/base_link.STL</uri>
            </mesh>
          </geometry>
          <max_contacts>10</max_contacts>
          <surface>
            <contact>
              <ode/>
            </contact>
            <bounce/>
            <friction>
              <torsional>
                <ode/>
              </torsional>
              <ode/>
            </friction>
          </surface>
        </collision>
        <visual name='base_link_visual'>
          <pose>0 0 0 0 -0 0</pose>
          <geometry>
            <mesh>
              <scale>1 1 1</scale>
              <uri>file:///home/legacy/trr_robot_ws/src/robot/meshes/base_link.STL</uri>
            </mesh>
          </geometry>
        </visual>
        <self_collide>0</self_collide>
        <enable_wind>0</enable_wind>
        <kinematic>0</kinematic>
      </link>
      <joint name='T_joint' type='revolute'>
        <pose relative_to='base_link'>0 0 0.19042 -1.56759 -1.57079 3.14159</pose>
        <parent>base_link</parent>
        <child>Link_1</child>
        <axis>
          <xyz>1 0 0</xyz>
          <limit>
            <lower>-1e+16</lower>
            <upper>1e+16</upper>
          </limit>
          <dynamics>
            <spring_reference>0</spring_reference>
            <spring_stiffness>0</spring_stiffness>
          </dynamics>
        </axis>
      </joint>
      <link name='Link_1'>
        <pose relative_to='T_joint'>0 0 0 0 -0 0</pose>
        <inertial>
          <pose>0.209045 -0 -0.000639 0 -0 0</pose>
          <mass>1.4077</mass>
          <inertia>
            <ixx>0.000166151</ixx>
            <ixy>2.39277e-13</ixy>
            <ixz>2.96592e-05</ixz>
            <iyy>0.0103245</iyy>
            <iyz>-1.22366e-14</iyz>
            <izz>0.0102914</izz>
          </inertia>
        </inertial>
        <collision name='Link_1_collision'>
          <pose>0 0 0 0 -0 0</pose>
          <geometry>
            <mesh>
              <scale>1 1 1</scale>
              <uri>file:///home/legacy/trr_robot_ws/src/robot/meshes/Link_1.STL</uri>
            </mesh>
          </geometry>
          <max_contacts>10</max_contacts>
          <surface>
            <contact>
              <ode/>
            </contact>
            <bounce/>
            <friction>
              <torsional>
                <ode/>
              </torsional>
              <ode/>
            </friction>
          </surface>
        </collision>
        <collision name='Link_1_pas_collision_1'>
          <pose>0.242 0 0 -1.5708 -0 -1.5686</pose>
          <geometry>
            <mesh>
              <scale>1 1 1</scale>
              <uri>file:///home/legacy/trr_robot_ws/src/robot/meshes/Link_1_pas.STL</uri>
            </mesh>
          </geometry>
          <max_contacts>10</max_contacts>
          <surface>
            <contact>
              <ode/>
            </contact>
            <bounce/>
            <friction>
              <torsional>
                <ode/>
              </torsional>
              <ode/>
            </friction>
          </surface>
        </collision>
        <visual name='Link_1_visual'>
          <pose>0 0 0 0 -0 0</pose>
          <geometry>
            <mesh>
              <scale>1 1 1</scale>
              <uri>file:///home/legacy/trr_robot_ws/src/robot/meshes/Link_1.STL</uri>
            </mesh>
          </geometry>
        </visual>
        <visual name='Link_1_pas_visual_1'>
          <pose>0.242 0 0 -1.5708 -0 -1.5686</pose>
          <geometry>
            <mesh>
              <scale>1 1 1</scale>
              <uri>file:///home/legacy/trr_robot_ws/src/robot/meshes/Link_1_pas.STL</uri>
            </mesh>
          </geometry>
        </visual>
        <self_collide>0</self_collide>
        <enable_wind>0</enable_wind>
        <kinematic>0</kinematic>
      </link>
      <joint name='R1_joint' type='revolute'>
        <pose relative_to='Link_1'>0.242 0 0 -1.5708 -0 -1.5686</pose>
        <parent>Link_1</parent>
        <child>Link_2</child>
        <axis>
          <xyz>0 1 0</xyz>
          <limit>
            <lower>-1e+16</lower>
            <upper>1e+16</upper>
          </limit>
          <dynamics>
            <spring_reference>0</spring_reference>
            <spring_stiffness>0</spring_stiffness>
          </dynamics>
        </axis>
      </joint>
      <link name='Link_2'>
        <pose relative_to='R1_joint'>0 0 0 0 -0 0</pose>
        <inertial>
          <pose>0 -0.000701 0.222363 0 -0 0</pose>
          <mass>1.28385</mass>
          <inertia>
            <ixx>0.00511645</ixx>
            <ixy>-3.0178e-19</ixy>
            <ixz>2.56422e-17</ixz>
            <iyy>0.00512969</iyy>
            <iyz>2.4873e-05</iyz>
            <izz>4.6923e-05</izz>
          </inertia>
        </inertial>
        <collision name='Link_2_collision'>
          <pose>0 0 0 0 -0 0</pose>
          <geometry>
            <mesh>
              <scale>1 1 1</scale>
              <uri>file:///home/legacy/trr_robot_ws/src/robot/meshes/Link_2.STL</uri>
            </mesh>
          </geometry>
          <max_contacts>10</max_contacts>
          <surface>
            <contact>
              <ode/>
            </contact>
            <bounce/>
            <friction>
              <torsional>
                <ode/>
              </torsional>
              <ode/>
            </friction>
          </surface>
        </collision>
        <collision name='Link_2_pas_collision_1'>
          <pose>0 0 0.25 0 -0.015943 0</pose>
          <geometry>
            <mesh>
              <scale>1 1 1</scale>
              <uri>file:///home/legacy/trr_robot_ws/src/robot/meshes/Link_2_pas.STL</uri>
            </mesh>
          </geometry>
          <max_contacts>10</max_contacts>
          <surface>
            <contact>
              <ode/>
            </contact>
            <bounce/>
            <friction>
              <torsional>
                <ode/>
              </torsional>
              <ode/>
            </friction>
          </surface>
        </collision>
        <visual name='Link_2_visual'>
          <pose>0 0 0 0 -0 0</pose>
          <geometry>
            <mesh>
              <scale>1 1 1</scale>
              <uri>file:///home/legacy/trr_robot_ws/src/robot/meshes/Link_2.STL</uri>
            </mesh>
          </geometry>
        </visual>
        <visual name='Link_2_pas_visual_1'>
          <pose>0 0 0.25 0 -0.015943 0</pose>
          <geometry>
            <mesh>
              <scale>1 1 1</scale>
              <uri>file:///home/legacy/trr_robot_ws/src/robot/meshes/Link_2_pas.STL</uri>
            </mesh>
          </geometry>
        </visual>
        <self_collide>0</self_collide>
        <enable_wind>0</enable_wind>
        <kinematic>0</kinematic>
      </link>
      <joint name='R2_joint' type='revolute'>
        <pose relative_to='Link_2'>0 0 0.25 3.13934 0 -1.5708</pose>
        <parent>Link_2</parent>
        <child>Link_3</child>
        <axis>
          <xyz>1 0 0</xyz>
          <limit>
            <lower>-1e+16</lower>
            <upper>1e+16</upper>
          </limit>
          <dynamics>
            <spring_reference>0</spring_reference>
            <spring_stiffness>0</spring_stiffness>
          </dynamics>
        </axis>
      </joint>
      <link name='Link_3'>
        <pose relative_to='R2_joint'>0 0 0 0 -0 0</pose>
        <inertial>
          <pose>0 -0.210765 0 0 -0 0</pose>
          <mass>0.26359</mass>
          <inertia>
            <ixx>0.00372379</ixx>
            <ixy>1.00919e-16</ixy>
            <ixz>-5.63678e-22</ixz>
            <iyy>9.02563e-05</iyy>
            <iyz>6.76504e-18</iyz>
            <izz>0.00375533</izz>
          </inertia>
        </inertial>
        <collision name='Link_3_collision'>
          <pose>0 0 0 0 -0 0</pose>
          <geometry>
            <mesh>
              <scale>1 1 1</scale>
              <uri>file:///home/legacy/trr_robot_ws/src/robot/meshes/Link_3.STL</uri>
            </mesh>
          </geometry>
          <max_contacts>10</max_contacts>
          <surface>
            <contact>
              <ode/>
            </contact>
            <bounce/>
            <friction>
              <torsional>
                <ode/>
              </torsional>
              <ode/>
            </friction>
          </surface>
        </collision>
        <visual name='Link_3_visual'>
          <pose>0 0 0 0 -0 0</pose>
          <geometry>
            <mesh>
              <scale>1 1 1</scale>
              <uri>file:///home/legacy/trr_robot_ws/src/robot/meshes/Link_3.STL</uri>
            </mesh>
          </geometry>
        </visual>
        <self_collide>0</self_collide>
        <enable_wind>0</enable_wind>
        <kinematic>0</kinematic>
      </link>
      <static>0</static>
      <plugin name='gazebo_ros2_control' filename='libgazebo_ros2_control.so'>
        <parameters>/home/legacy/trr_robot_ws/src/robot/config/joint_controller.yaml</parameters>
      </plugin>
      <pose>0 0 0 0 -0 0</pose>
    </model>
    <state world_name='default'>
      <sim_time>924 304000000</sim_time>
      <real_time>282 849794045</real_time>
      <wall_time>1639588524 677551120</wall_time>
      <iterations>282073</iterations>
      <model name='ground_plane'>
        <pose>0 0 0 0 -0 0</pose>
        <scale>1 1 1</scale>
        <link name='link'>
          <pose>0 0 0 0 -0 0</pose>
          <velocity>0 0 0 0 -0 0</velocity>
          <acceleration>0 0 0 0 -0 0</acceleration>
          <wrench>0 0 0 0 -0 0</wrench>
        </link>
      </model>
      <model name='robot'>
        <pose>-0 -1.7e-05 2.7e-05 -0.000407 3e-06 -1e-06</pose>
        <scale>1 1 1</scale>
        <link name='Link_1'>
          <pose>5.9e-05 -0.001032 0.19045 3.00721 -1.56821 -1.66369</pose>
          <velocity>-0.00244 0.004217 -0.000694 -0.013688 0.069988 1.97999</velocity>
          <acceleration>-0.358175 2.89415 -0.168756 2.84196 0.26967 -0.544943</acceleration>
          <wrench>-0.504203 4.07409 -0.237557 0 -0 0</wrench>
        </link>
        <link name='Link_2'>
          <pose>0.010207 -0.020706 0.446924 0.110352 -0.157637 -0.241169</pose>
          <velocity>-0.552589 -0.863981 0.650873 -1.95745 -0.110122 -0.155295</velocity>
          <acceleration>-16.7747 11.1954 -1.87561 1.84223 0.132266 1.81136</acceleration>
          <wrench>-21.5363 14.3732 -2.40801 0 -0 0</wrench>
        </link>
        <link name='Link_3'>
          <pose>0.239608 0.410012 0.59677 2.89744 -1.02731 -1.75094</pose>
          <velocity>31.0137 0.887648 3.57299 1.8497 -0.671014 -0.086383</velocity>
          <acceleration>84.8114 132.557 -28.8698 -1.19068 -0.922928 -2.33241</acceleration>
          <wrench>22.3554 34.9408 -7.60979 0 -0 0</wrench>
        </link>
        <link name='base_link'>
          <pose>-0 -1.7e-05 2.7e-05 -0.000407 3e-06 -1e-06</pose>
          <velocity>-4e-06 -0.000128 -0.000666 -0.01878 0.000365 1.8e-05</velocity>
          <acceleration>-0.000347 0.093951 -0.164237 1.82206 -0.006281 0.004036</acceleration>
          <wrench>-0.00207 0.561383 -0.981365 0 -0 0</wrench>
        </link>
      </model>
      <light name='sun'>
        <pose>0 0 10 0 -0 0</pose>
      </light>
    </state>
    <gui fullscreen='0'>
      <camera name='user_camera'>
        <pose>-0.019228 -1.45656 1.45019 0 0.559643 1.6162</pose>
        <view_controller>orbit</view_controller>
        <projection_type>perspective</projection_type>
      </camera>
    </gui>
  </world>
</sdf>
